Workbook
Name 補完_階床候補: 塔内機器_入力①_DB!$C$2:$C$937

Sheet 補完ガイド
B2: SA900-01 据付寸法自動計算ツール
B3: iReporter向け修正版 v2 / 2026-09-20
B4: 推定部品は確認記録が揃うまで出力を停止します。基本入力・寸法・階高を変更すると、各出力の状態表示も更新します。
B7: 現在の入力と参照状態
B8: 階床名 | C8: =帳票基本入力!C5 -> 1-7 | E8: 部品DBキー | F8: =塔内機器_計算用シート!R4 -> UA-25TP900有
B9: 階床DB | C9: =IF(塔内機器_計算用シート!Y4<>1,"未登録・重複",IF(COUNTIF(塔内機器_入力①_DB!$C$201:$C$937,C8)>0,"補完・追記","原データ")) -> 補完・追記 | E9: 部品DB | F9: =IFERROR(VLOOKUP(F8,塔内機器_出力②_DB!$M$4:$O$23,3,FALSE),"未登録") -> 原データ
B10: 計算の確認 | C10: =塔内機器_計算用シート!Y23 -> 参照範囲内（設計妥当性は要照合）
B12: 操作
B13: 1. 帳票基本入力を設定 | E13: 2. 機種・寸法・階高を入力
B14: 3. 出力①・②を確認 | E14: 4. 出力③の部品を確認
B16: 補完・修正した内容
B17: 階床DB | C17: 候補・数式・判定の範囲を2～937行に統一。追記を自動参照。
B18: 取付階 | C18: 空階を近似検索から除外。最上階の階名を正しく表示。
B19: 入力確認 | C19: 整数・必須・範囲・階高合計・未使用欄の残値を検査。
B20: 推定部品 | C20: 出力②_DB の V～Z列へ資料・版・確認者・日付・判定を記録。
B21: 計算負荷 | C21: 固定DBキーを値にし、同じ階床の二重検索を解消。
B22: 誤操作防止 | C22: 数式とDBを保護。保守時はパスワードなしで保護解除。
B23: 画面・印刷 | C23: 基本入力を1ページに集約。DBは表示を保ち、帳票印刷対象外。
B24: マスター | C24: 復元マスターとv1を変更せず、別ファイルとして保存。
B26: 推定DBの内訳
B27: 区分 | C27: 機種 | D27: OP | E27: 遮煙 | F27: 行 | G27: 転用元
B28: 一部推定 | C28: UAE-25T | D28: 1000 | E28: 無 | F28: 501–507 | G28: グループ105
B29: 推定・要照合 | C29: UAE-25T | D29: 1000 | E29: 有 | F29: 508–563 | G29: グループ106
B30: 推定・要照合 | C30: UAE-25T | D30: 1100 | E30: 無 | F30: 564–619 | G30: グループ107
B31: 推定・要照合 | C31: UAE-25T | D31: 1100 | E31: 有 | F31: 620–675 | G31: グループ108
B32: 推定・要照合 | C32: UA-25TR | D32: 800 | E32: 無 | F32: 676–731 | G32: グループ101
B33: 推定・要照合 | C33: UA-25TR | D33: 800 | E33: 有 | F33: 732–787 | G33: グループ102
B34: 推定・要照合 | C34: UA-25TR | D34: 900 | E34: 無 | F34: 788–843 | G34: グループ103
B35: 推定・要照合 | C35: UA-25TR | D35: 900 | E35: 有 | F35: 844–899 | G35: グループ104
B36: 推定・要照合 | C36: UA-25TB | D36: 1100 | E36: 無 | F36: 900–955 | G36: グループ107
B37: 推定・要照合 | C37: UA-25TB | D37: 1100 | E37: 有 | F37: 956–1011 | G37: グループ108
B38: 推定・要照合 | C38: UA-25TB | D38: 1200 | E38: 無 | F38: 1012–1067 | G38: グループ107
B39: 推定・要照合 | C39: UA-25TB | D39: 1200 | E39: 有 | F39: 1068–1123 | G39: グループ108
B41: 残っている制限
B42: ExcelOutputSetting・クラスター設定の欠落は今回の修正対象外です。iPhone上の計算・入力制御は、設定を復元した後に実機確認が必要です。
B44: 階床DBは937行まで追記可能。部品DBの追加・並べ替え・寸法変更時は固定キーを再生成し、検証を再実行してください。推定内容そのもののメーカー照合は未実施です。
B47: 作成者: Codex (GPT-6) / マスター保存・推定補完・検証結果を別紙に記録

Sheet 帳票基本入力
B2: SA900-01 帳票基本入力
B3: 機種・寸法・階高は「塔内機器_入力①」に入力します。
B5: 階床名 | C5: 1-7
B6: 元機種仕様（P型） | C6: UAP-13-2S45
B7: Cwtセフティ | C7: Cwtｾﾌﾃｨ付
B8: テールコード落ち方 | C8: 後落ち
B9: 制御盤距離（mm） | C9: 3080
B11: 入力条件
B12: =塔内機器_計算用シート!Y16 -> 入力条件成立
B15: 部品の参照状態
B16: =塔内機器_計算用シート!Y18 -> 参照範囲内（設計妥当性は要照合）
B19: 制御盤距離は従来の出力② B13の入力値です。 黄色が入力欄です。推定部品はDBの確認記録が揃うまで出力しません。階床変更後は未使用の階高を消してください。
B23: =CONCATENATE(塔内機器_計算用シート!AH42," / 2026-09-24 境界条件修正") -> v4 / 2026-09-24 境界条件修正

Sheet 入力表
A1: 復元時の入力データ（計算条件は「帳票基本入力」で設定）
G3: =MID(E12,15,5)
A4: CSV連携項目
A5: No | B5: 項目名 | E5: 値 | F5: No | G5: 項目名 | J5: 値
A6: 0 | B6: 依頼番号 | F6: 16 | G6: ラベル4
A7: 1 | B7: 作番 | F7: 17 | G7: ラベル5
A8: 2 | B8: 帳票シートID | F8: 18 | G8: ラベル6
A9: 3 | B9: リンク先 | E9: =CONCATENATE(E10,E11,"/",E12,"/",E13,"/",E14,"/",E15) -> 新設・改販///_/ | F9: 19 | G9: ラベル7
A10: 4 | B10: テナント情報 | F10: 20 | G10: ラベル8
A11: 5 | B11: フォルダ1 | E11: ="新設・改販" -> 新設・改販 | F11: 21 | G11: 作成日(年/月/日)yy/㎜/dd
A12: 6 | B12: 作番現場名(フォルダ2) | F12: 22 | G12: 件名(作業指示件名)
A13: 7 | B13: フォルダ3用データ | F13: 23 | G13: Ｅ作番
A14: 8 | B14: フォルダ4 | E14: =CONCATENATE(E6,"_",J15) -> _ | F14: 24 | G14: 協力会社コード
A15: 9 | B15: フォルダ5 | E15: =IF(J7<>"",J7,"") | F15: 25 | G15: 協力会社名（正式）
A16: 10 | B16: 項目マスタID | F16: 26 | G16: 協力会社名（短縮）
A17: 11 | B17: 水戸作番(セ番) | F17: 27 | G17: 表紙フラグ
A18: 12 | B18: (水)項番 | F18: 28 | G18: 予備1
A19: 13 | B19: ラベル1 | F19: 29 | G19: 予備2
A20: 14 | B20: ラベル2 | F20: 30 | G20: 予備3
A21: 15 | B21: ラベル3 | F21: 31 | G21: 予備4
A23: GateWay連携項目
A24: No | B24: 項目名 | E24: 値 | F24: No | G24: 項目名 | J24: 値
A25: 審査情報
A26: 32 | B26: 作成日 | F26: 37 | G26: 承認者
A27: 33 | B27: 作成者 | F27: 38 | G27: 予備１
A28: 34 | B28: 審査日 | F28: 39 | G28: 予備２
A29: 35 | B29: 審査者 | F29: 40 | G29: 予備３
A30: 36 | B30: 承認日 | F30: 41 | G30: 予備４
A31: 基本情報
A32: 42 | B32: 現場名 | F32: 54 | G32: 階床名 | J32: 1-7
A33: 43 | B33: 住所 | F33: 55 | G33: 工事工法
A34: 44 | B34: 保全セ＃ | F34: 56 | G34: 作業内容1
A35: 45 | B35: 品名型式 | E35: UAP-13-2S45 | F35: 57 | G35: 作業内容2
A36: 46 | B36: 機種コード | F36: 58 | G36: 作業内容3
A37: 47 | B37: 号機 | F37: 59 | G37: 作業内容4
A38: 48 | B38: 台数 | F38: 60 | G38: 作業内容5
A39: 49 | B39: 停止 | F39: 61 | G39: 予備1
A40: 50 | B40: 不停止 | F40: 62 | G40: 予備2
A41: 51 | B41: 速度 | F41: 63 | G41: 予備3
A42: 52 | B42: 積載量 | F42: 64 | G42: 予備4
...

Sheet 情報更新画面
D1: 改定日：２０２３年３月１日
E4: 情報更新画面
E11: 手動入力 | AE11: 外部連携は未収録 入力表へ直接入力 | CB11: 入力表へ

Sheet 目次
B2: 目次 | O2: 自動計算ツール
B8: 基準芯出し自動計算ツール | U8: 未収録
B11: 適用機種 ：UA-21G，UA-23T 適用外 ：１．出入口二方向 ２．【UA-21G】巻上機・制御盤嵩上げ仕様 ３．【UA-23T】UAEP形式,4P-CO仕様
B19: トップレール加工要否検討ツール | U19: 未収録
B22: 適用機種 ：UA-21G 適用外 ：１．工場でレール切断がされている場合 ２．下記仕様条件をすべて満たす場合 ①R 9（二方向）, ②定格速度 105m/min,③可変速仕様有り ④行程:30m 以下,⑤ CwtRG:550 ㎜
B32: レール調整プレート自動計算ツール | U32: 未収録
B35: 適用機種 ：UA-23T 適用外 ：レール高さ調整機構"無し"時
B41: レール高さ調整機構無し時の 対応方法選定フロー検討ツール
U42: 未収録
B46: 適用機種 ：UA-23T 適用外 ：レール高さ調整機構"有り"時
B52: 塔内機器取付位置自動計算ツール | U52: ツール画面
B55: 適用機種 ：UA-21G，UA-23T 適用外 ：【UA-21G】巻上機・制御盤嵩上げ仕様 【UA-23T】4P-CO仕様 一部機能適用外
B62: 遮蔽板取付位置自動計算ツール | U62: 未収録
B65: 適用機種 ：UA-23T 適用外 ：無し

Sheet 塔内機器_表紙
B2: 表紙 | O2: 塔内機器取付位置計算ツール
B5: 塔内機器取付位置計算ツール概要 ・塔内機器(ガバナロープ振れ止め、主ロープ振れ止め、テールコード玉返し、フェッシャープレート)の取付位置を検討するツール 適用機種 ：UA-21G，UA-23T 適用外 ：【UA-21G】巻上機・制御盤嵩上げ仕様 【UA-23T】4P-CO仕様 一部機能適用外

Sheet 塔内機器_入力①
B2: 作番の情報を入力 | O2: 塔内機器取付位置計算ツール (1/4)
B6: ①作番 | P6: ②現場名
B12: ③機種コード | P12: ④OP
B14: UA-25TP | P14: 900
B17: =IF(MID(B14,3,1)="E",MID(B14,5,2),MID(B14,4,2)) -> 25 | C17: =MID(B14,6,1) -> T
B18: ⑤全高 ※仮想OH有は、仮想OHまでの寸法記入 | P18: ⑥行程
B20: 24470 | L20: ｍｍ | P20: 20145 | Z20: ｍｍ
B24: ⑦ピット深さ寸法 | P24: ⑧出入口遮煙仕様
B26: 1300 | L26: ｍｍ | P26: 有
B32: ⑨階高寸法
B34: 階 | E34: 階高(mm) | K34: 階 | N34: 階高(mm) | T34: 階 | W34: 階高(mm)
B36: =IF(塔内機器_計算用シート!Z45=0,"",CONCATENATE(塔内機器_計算用シート!Z45)) -> 1 | K36: =IF(塔内機器_計算用シート!Z53=0,"",CONCATENATE(塔内機器_計算用シート!Z53)) | T36: =IF(塔内機器_計算用シート!Z61=0,"",CONCATENATE(塔内機器_計算用シート!Z61))
E38: 3745
B40: =IF(塔内機器_計算用シート!Z46=0,"",CONCATENATE(塔内機器_計算用シート!Z46)) -> 2 | K40: =IF(塔内機器_計算用シート!Z54=0,"",CONCATENATE(塔内機器_計算用シート!Z54)) | T40: =IF(塔内機器_計算用シート!Z62=0,"",CONCATENATE(塔内機器_計算用シート!Z62))
E42: 3300
B44: =IF(塔内機器_計算用シート!Z47=0,"",CONCATENATE(塔内機器_計算用シート!Z47)) -> 3 | K44: =IF(塔内機器_計算用シート!Z55=0,"",CONCATENATE(塔内機器_計算用シート!Z55)) | T44: =IF(塔内機器_計算用シート!Z63=0,"",CONCATENATE(塔内機器_計算用シート!Z63))
E46: 3300
B48: =IF(塔内機器_計算用シート!Z48=0,"",CONCATENATE(塔内機器_計算用シート!Z48)) -> 4 | K48: =IF(塔内機器_計算用シート!Z56=0,"",CONCATENATE(塔内機器_計算用シート!Z56)) | T48: =IF(塔内機器_計算用シート!Z64=0,"",CONCATENATE(塔内機器_計算用シート!Z64))
E50: 3300
B52: =IF(塔内機器_計算用シート!Z49=0,"",CONCATENATE(塔内機器_計算用シート!Z49)) -> 5 | K52: =IF(塔内機器_計算用シート!Z57=0,"",CONCATENATE(塔内機器_計算用シート!Z57)) | T52: =IF(塔内機器_計算用シート!Z65=0,"",CONCATENATE(塔内機器_計算用シート!Z65))
E54: 3250
B56: =IF(塔内機器_計算用シート!Z50=0,"",CONCATENATE(塔内機器_計算用シート!Z50)) -> 6 | K56: =IF(塔内機器_計算用シート!Z58=0,"",CONCATENATE(塔内機器_計算用シート!Z58)) | T56: =IF(塔内機器_計算用シート!Z66=0,"",CONCATENATE(塔内機器_計算用シート!Z66))
E58: 3250
B60: =IF(塔内機器_計算用シート!Z51=0,"",CONCATENATE(塔内機器_計算用シート!Z51)) -> 7 | K60: =IF(塔内機器_計算用シート!Z59=0,"",CONCATENATE(塔内機器_計算用シート!Z59)) | T60: =IF(塔内機器_計算用シート!Z67=0,"",CONCATENATE(塔内機器_計算用シート!Z67))
B64: =IF(塔内機器_計算用シート!Z52=0,"",CONCATENATE(塔内機器_計算用シート!Z52)) | K64: =IF(塔内機器_計算用シート!Z60=0,"",CONCATENATE(塔内機器_計算用シート!Z60)) | T64: =IF(塔内機器_計算用シート!Z68=0,"",CONCATENATE(塔内機器_計算用シート!Z68))
B69: =IF(塔内機器_計算用シート!Y15=1,"",塔内機器_計算用シート!Y16)
B74: =CONCATENATE("v2 ",塔内機器_計算用シート!Y23) -> v2 参照範囲内（設計妥当性は要照合）

Sheet 塔内機器_出力①
B2: 塔内機器取付位置の確認① | O2: 塔内機器取付位置計算ツール (2/4)
B6: Cwtセフティの判定
B9: Cwtセフティ付きか
B11: =帳票基本入力!C7 -> Cwtｾﾌﾃｨ付
B15: ガバナロープ振れ止め員数及び取付位置の確認
B19: =IF($M$19="","","ガバナロープ振れ止め手配員数") -> ガバナロープ振れ止め手配員数 | L19: =IF($M$19="","","：") -> ： | M19: =IF(OR(塔内機器_計算用シート!AH40=0,塔内機器_計算用シート!AH37=0),"",塔内機器_計算用シート!AH37) -> 1 | R19: =IF($M$19="","","ヶ") -> ヶ
B22: =IF(塔内機器_計算用シート!Y15=0,塔内機器_計算用シート!Y16,IF(塔内機器_計算用シート!AH41<>"",塔内機器_計算用シート!AH41,IF(塔内機器_計算用シート!AH37=0,"本現場ではガバナロープ振れ止めの取付は不要","取付位置は参考値。Ｓ造の場合は保護番線の取付も考慮（規定値はマニュアル参照）。"))) -> 取付位置は参考値。Ｓ造の場合は保護番線の取付も考慮（規定値はマニュアル参照）。
B27: =IF(塔内機器_計算用シート!$D$4="","","１つ目は") -> １つ目は | E27: =IF(塔内機器_計算用シート!$D$4="","",VLOOKUP(塔内機器_計算用シート!$D$4,塔内機器_計算用シート!$L$5:$Q$28,6,TRUE)) -> 4 | H27: =IF(塔内機器_計算用シート!$D$4="","","階ＦＬから") -> 階ＦＬから | M27: =IF(塔内機器_計算用シート!$D$4="","",塔内機器_計算用シート!$D$4-VLOOKUP(塔内機器_計算用シート!$D$4,塔内機器_計算用シート!$L$5:$Q$28,1,TRUE)) -> 590 | R27: =IF(塔内機器_計算用シート!$D$4="","","mm") -> mm | T27: =IF(塔内機器_計算用シート!$D$4="","","の位置に取付けること") -> の位置に取付けること
B30: =IF(塔内機器_計算用シート!$D$5="","","２つ目は") | E30: =IF(塔内機器_計算用シート!$D$5="","",VLOOKUP(塔内機器_計算用シート!$D$5,塔内機器_計算用シート!$L$5:$Q$28,6,TRUE)) | H30: =IF(塔内機器_計算用シート!$D$5="","","階ＦＬから") | M30: =IF(塔内機器_計算用シート!$D$5="","",塔内機器_計算用シート!$D$5-VLOOKUP(塔内機器_計算用シート!$D$5,塔内機器_計算用シート!$L$5:$Q$28,1,TRUE)) | R30: =IF(塔内機器_計算用シート!$D$5="","","mm") | T30: =IF(塔内機器_計算用シート!$D$5="","","の位置に取付けること")
B33: =IF(塔内機器_計算用シート!$D$6="","","３つ目は") | E33: =IF(塔内機器_計算用シート!$D$6="","",VLOOKUP(塔内機器_計算用シート!$D$6,塔内機器_計算用シート!$L$5:$Q$28,6,TRUE)) | H33: =IF(塔内機器_計算用シート!$D$6="","","階ＦＬから") | M33: =IF(塔内機器_計算用シート!$D$6="","",塔内機器_計算用シート!$D$6-VLOOKUP(塔内機器_計算用シート!$D$6,塔内機器_計算用シート!$L$5:$Q$28,1,TRUE)) | R33: =IF(塔内機器_計算用シート!$D$6="","","mm") | T33: =IF(塔内機器_計算用シート!$D$6="","","の位置に取付けること")
B36: =IF(塔内機器_計算用シート!$D$7="","","４つ目は") | E36: =IF(塔内機器_計算用シート!$D$7="","",VLOOKUP(塔内機器_計算用シート!$D$7,塔内機器_計算用シート!$L$5:$Q$28,6,TRUE)) | H36: =IF(塔内機器_計算用シート!$D$7="","","階ＦＬから") | M36: =IF(塔内機器_計算用シート!$D$7="","",塔内機器_計算用シート!$D$7-VLOOKUP(塔内機器_計算用シート!$D$7,塔内機器_計算用シート!$L$5:$Q$28,1,TRUE)) | R36: =IF(塔内機器_計算用シート!$D$7="","","mm") | T36: =IF(塔内機器_計算用シート!$D$7="","","の位置に取付けること")
B39: =IF(塔内機器_計算用シート!$D$8="","","５つ目は") | E39: =IF(塔内機器_計算用シート!$D$8="","",VLOOKUP(塔内機器_計算用シート!$D$8,塔内機器_計算用シート!$L$5:$Q$28,6,TRUE)) | H39: =IF(塔内機器_計算用シート!$D$8="","","階ＦＬから") | M39: =IF(塔内機器_計算用シート!$D$8="","",塔内機器_計算用シート!$D$8-VLOOKUP(塔内機器_計算用シート!$D$8,塔内機器_計算用シート!$L$5:$Q$28,1,TRUE)) | R39: =IF(塔内機器_計算用シート!$D$8="","","mm") | T39: =IF(塔内機器_計算用シート!$D$8="","","の位置に取付けること")
B42: =IF(塔内機器_計算用シート!$D$9="","","６つ目は") | E42: =IF(塔内機器_計算用シート!$D$9="","",VLOOKUP(塔内機器_計算用シート!$D$9,塔内機器_計算用シート!$L$5:$Q$28,6,TRUE)) | H42: =IF(塔内機器_計算用シート!$D$9="","","階ＦＬから") | M42: =IF(塔内機器_計算用シート!$D$9="","",塔内機器_計算用シート!$D$9-VLOOKUP(塔内機器_計算用シート!$D$9,塔内機器_計算用シート!$L$5:$Q$28,1,TRUE)) | R42: =IF(塔内機器_計算用シート!$D$9="","","mm") | T42: =IF(塔内機器_計算用シート!$D$9="","","の位置に取付けること")
B89: =CONCATENATE(塔内機器_計算用シート!AH42," ",IF(塔内機器_計算用シート!AH41<>"",塔内機器_計算用シート!AH41,塔内機器_計算用シート!Y23)) -> v4 参照範囲内（設計妥当性は要照合）

Sheet 塔内機器_出力②
B2: 塔内機器取付位置の確認② | O2: 塔内機器取付位置計算ツール (3/4)
B8: 制御盤位置の確認
B11: 最上階FLから制御盤下端までの距離
B13: =IF(帳票基本入力!C9="","",帳票基本入力!C9) -> 3080 | L13: ｍｍ
Z16: =IF(塔内機器_計算用シート!Y39=0,"",塔内機器_計算用シート!Y37) -> 3
B17: テールコードブラケットの員数及び取付位置の確認
B20: =IF(塔内機器_計算用シート!Y39=0,"","テールコードタイプ") -> テールコードタイプ | T20: =IF(塔内機器_計算用シート!Y39=0,"","：") -> ： | U20: =IF(塔内機器_計算用シート!Y39=0,"",塔内機器_計算用シート!Y38) -> Lタイプ
B23: =IF(塔内機器_計算用シート!Y39=0,"","[ 1 ]") -> [ 1 ] | D23: =IF(塔内機器_計算用シート!Y39=0,"","ケーブルサポートブラ手配員数") -> ケーブルサポートブラ手配員数 | T23: =IF(塔内機器_計算用シート!Y39=0,"","：") -> ： | U23: =IF(塔内機器_計算用シート!Y39=0,"",塔内機器_計算用シート!Y25) -> 2 | Z23: =IF(塔内機器_計算用シート!Y39=0,"","ヶ") -> ヶ
B26: =IF(塔内機器_計算用シート!Y39=0,"","[ 2 ]") -> [ 2 ] | D26: =IF(塔内機器_計算用シート!Y39=0,"","テールコードサポートブラ手配員数") -> テールコードサポートブラ手配員数 | T26: =IF(塔内機器_計算用シート!Y39=0,"","：") -> ： | U26: =IF(塔内機器_計算用シート!Y39=0,"",塔内機器_計算用シート!Y36) -> 1 | Z26: =IF(塔内機器_計算用シート!Y39=0,"","ヶ") -> ヶ
B28: =IF(塔内機器_計算用シート!Y39=0,"",IF(B26="","","※テールコード2､3本時は1箇所当たり2ケ/セット取付のため注意")) -> ※テールコード2､3本時は1箇所当たり2ケ/セット取付のため注意
B30: =IF(L30="","","1つ目は") -> 1つ目は | E30: =IF(塔内機器_計算用シート!D31="","",VLOOKUP(塔内機器_計算用シート!D31,塔内機器_計算用シート!$I$5:$Q$28,9,TRUE)) -> 4 | H30: =IF(L30="","","階FLから") -> 階FLから | L30: =IF(塔内機器_計算用シート!D31="","",塔内機器_計算用シート!D31-VLOOKUP(塔内機器_計算用シート!D31,塔内機器_計算用シート!$I$5:$Q$28,1,TRUE)) -> 227.5 | Q30: =IF(L30="","","ｍｍ") -> ｍｍ | S30: =IF(L30="","","の位置に") -> の位置に | V30: =IF(L30="","",IF(塔内機器_計算用シート!Y36=2,"[ 2 ]","[ 1 ]")) -> [ 1 ] | Y30: =IF(L30="","","を取付け") -> を取付け
I33: =IF(M33="","","ピッチは") -> ピッチは | M33: =IF(塔内機器_計算用シート!D32="","",塔内機器_計算用シート!D32-塔内機器_計算用シート!D31) -> 5399 | S33: =IF(M33="","","ｍｍ") -> ｍｍ
B35: =IF(L35="","","2つ目は") -> 2つ目は | E35: =IF(塔内機器_計算用シート!D32="","",VLOOKUP(塔内機器_計算用シート!D32,塔内機器_計算用シート!$I$5:$Q$28,9,TRUE)) -> 5 | H35: =IF(L35="","","階FLから") -> 階FLから | L35: =IF(塔内機器_計算用シート!D32="","",塔内機器_計算用シート!D32-VLOOKUP(塔内機器_計算用シート!D32,塔内機器_計算用シート!$I$5:$Q$28,1,TRUE)) -> 2326.5 | Q35: =IF(L35="","","ｍｍ") -> ｍｍ | S35: =IF(L35="","","の位置に") -> の位置に | V35: =IF(L35="","",IF(塔内機器_計算用シート!Y37=2,"[ 2 ]","[ 1 ]")) -> [ 1 ] | Y35: =IF(L35="","","を取付け") -> を取付け
I38: =IF(M38="","","ピッチは") -> ピッチは | M38: =IF(塔内機器_計算用シート!D33="","",塔内機器_計算用シート!D33-塔内機器_計算用シート!D32) -> 5398.5 | S38: =IF(M38="","","ｍｍ") -> ｍｍ
B40: =IF(L40="","","3つ目は") -> 3つ目は | E40: =IF(塔内機器_計算用シート!D33="","",VLOOKUP(塔内機器_計算用シート!D33,塔内機器_計算用シート!$I$5:$Q$28,9,TRUE)) -> 7 | H40: =IF(L40="","","階FLから") -> 階FLから | L40: =IF(塔内機器_計算用シート!D33="","",塔内機器_計算用シート!D33-VLOOKUP(塔内機器_計算用シート!D33,塔内機器_計算用シート!$I$5:$Q$28,1,TRUE)) -> 1225 | Q40: =IF(L40="","","ｍｍ") -> ｍｍ | S40: =IF(L40="","","の位置に") -> の位置に | V40: =IF(L40="","",IF(塔内機器_計算用シート!Y37=3,"[ 2 ]","[ 1 ]")) -> [ 2 ] | Y40: =IF(L40="","","を取付け") -> を取付け
M43: =IF(塔内機器_計算用シート!D34="","",塔内機器_計算用シート!D34-塔内機器_計算用シート!D33) | S43: =IF(M43="","","ｍｍ")
B45: =IF(L45="","","4つ目は") | E45: =IF(塔内機器_計算用シート!D34="","",VLOOKUP(塔内機器_計算用シート!D34,塔内機器_計算用シート!$I$5:$Q$28,9,TRUE)) | H45: =IF(L45="","","階FLから") | L45: =IF(塔内機器_計算用シート!D34="","",塔内機器_計算用シート!D34-VLOOKUP(塔内機器_計算用シート!D34,塔内機器_計算用シート!$I$5:$Q$28,1,TRUE)) | Q45: =IF(L45="","","ｍｍ") | S45: =IF(L45="","","の位置に") | V45: =IF(L45="","",IF(塔内機器_計算用シート!Y37=4,"[ 2 ]","[ 1 ]")) | Y45: =IF(L45="","","を取付け")
I48: =IF(M48="","","ピッチは") | M48: =IF(塔内機器_計算用シート!D35="","",塔内機器_計算用シート!D35-塔内機器_計算用シート!D34) | S48: =IF(M48="","","ｍｍ")
B50: =IF(L50="","","5つ目は") | E50: =IF(塔内機器_計算用シート!D35="","",VLOOKUP(塔内機器_計算用シート!D35,塔内機器_計算用シート!$I$5:$Q$28,9,TRUE)) | H50: =IF(L50="","","階FLから") | L50: =IF(塔内機器_計算用シート!D35="","",塔内機器_計算用シート!D35-VLOOKUP(塔内機器_計算用シート!D35,塔内機器_計算用シート!$I$5:$Q$28,1,TRUE)) | Q50: =IF(L50="","","ｍｍ") | S50: =IF(L50="","","の位置に") | V50: =IF(L50="","",IF(塔内機器_計算用シート!Y37=5,"[ 2 ]","[ 1 ]")) | Y50: =IF(L50="","","を取付け")
I53: =IF(M53="","","ピッチは") | M53: =IF(塔内機器_計算用シート!D36="","",塔内機器_計算用シート!D36-塔内機器_計算用シート!D35) | S53: =IF(M53="","","ｍｍ")
B55: =IF(L55="","","6つ目は") | E55: =IF(塔内機器_計算用シート!D36="","",VLOOKUP(塔内機器_計算用シート!D36,塔内機器_計算用シート!$I$5:$Q$28,9,TRUE)) | H55: =IF(L55="","","階FLから") | L55: =IF(塔内機器_計算用シート!D36="","",塔内機器_計算用シート!D36-VLOOKUP(塔内機器_計算用シート!D36,塔内機器_計算用シート!$I$5:$Q$28,1,TRUE)) | Q55: =IF(L55="","","ｍｍ") | S55: =IF(L55="","","の位置に") | V55: =IF(L55="","",IF(塔内機器_計算用シート!Y37=6,"[ 2 ]","[ 1 ]")) | Y55: =IF(L55="","","を取付け")
I58: =IF(M58="","","ピッチは") | M58: =IF(塔内機器_計算用シート!D37="","",塔内機器_計算用シート!D37-塔内機器_計算用シート!D36) | S58: =IF(M58="","","ｍｍ")
B60: =IF(L60="","","7つ目は") | E60: =IF(塔内機器_計算用シート!D37="","",VLOOKUP(塔内機器_計算用シート!D37,塔内機器_計算用シート!$I$5:$Q$28,9,TRUE)) | H60: =IF(L60="","","階FLから") | L60: =IF(塔内機器_計算用シート!D37="","",塔内機器_計算用シート!D37-VLOOKUP(塔内機器_計算用シート!D37,塔内機器_計算用シート!$I$5:$Q$28,1,TRUE)) | Q60: =IF(L60="","","ｍｍ") | S60: =IF(L60="","","の位置に") | V60: =IF(L60="","",IF(塔内機器_計算用シート!Y37=7,"[ 2 ]","[ 1 ]")) | Y60: =IF(L60="","","を取付け")
I63: =IF(M63="","","ピッチは") | M63: =IF(塔内機器_計算用シート!D38="","",塔内機器_計算用シート!D38-塔内機器_計算用シート!D37) | S63: =IF(M63="","","ｍｍ")
B65: =IF(L65="","","8つ目は") | E65: =IF(塔内機器_計算用シート!D38="","",VLOOKUP(塔内機器_計算用シート!D38,塔内機器_計算用シート!$I$5:$Q$28,9,TRUE)) | H65: =IF(L65="","","階FLから") | L65: =IF(塔内機器_計算用シート!D38="","",塔内機器_計算用シート!D38-VLOOKUP(塔内機器_計算用シート!D38,塔内機器_計算用シート!$I$5:$Q$28,1,TRUE)) | Q65: =IF(L65="","","ｍｍ") | S65: =IF(L65="","","の位置に") | V65: =IF(L65="","",IF(塔内機器_計算用シート!Y37=8,"[ 2 ]","[ 1 ]")) | Y65: =IF(L65="","","を取付け")
I68: =IF(M68="","","ピッチは") | M68: =IF(塔内機器_計算用シート!D39="","",塔内機器_計算用シート!D39-塔内機器_計算用シート!D38) | S68: =IF(M68="","","ｍｍ")
B70: =IF(L70="","","9つ目は") | E70: =IF(塔内機器_計算用シート!D39="","",VLOOKUP(塔内機器_計算用シート!D39,塔内機器_計算用シート!$I$5:$Q$28,9,TRUE)) | H70: =IF(L70="","","階FLから") | L70: =IF(塔内機器_計算用シート!D39="","",塔内機器_計算用シート!D39-VLOOKUP(塔内機器_計算用シート!D39,塔内機器_計算用シート!$I$5:$Q$28,1,TRUE)) | Q70: =IF(L70="","","ｍｍ") | S70: =IF(L70="","","の位置に") | V70: =IF(L70="","",IF(塔内機器_計算用シート!Y37=9,"[ 2 ]","[ 1 ]")) | Y70: =IF(L70="","","を取付け")
B75: =CONCATENATE(塔内機器_計算用シート!AH42," ",IF(塔内機器_計算用シート!AH36<>"",塔内機器_計算用シート!AH36,塔内機器_計算用シート!Y23)) -> v4 参照範囲内（設計妥当性は要照合）

Sheet 塔内機器_出力③
B2: 塔内機器取付位置の確認③ | O2: 塔内機器取付位置計算ツール (4/4)
B6: 各階フェッシャープレートの組合せを確認
J11: フェッシャー高さ（mm）【員数】
A14: 1 | B14: =IF(塔内機器_計算用シート!Y22=0,"",IF(塔内機器_入力①!$E$38<>"",塔内機器_入力①!$B36,"")) -> 1 | D14: ～ | E14: =IF(塔内機器_計算用シート!Y22=0,"",IF(塔内機器_入力①!$E$38<>"",塔内機器_入力①!$B40,"")) -> 2 | G14: 階 | I14: ： | J14: =IF(塔内機器_計算用シート!Y22=0,"",IF(1>MAX(塔内機器_計算用シート!$E$45:$E$68)-1,"",IFERROR(VLOOKUP(1,塔内機器_計算用シート!$E$45:$K$68,7,FALSE),""))) -> 420【1】+800【1】
A15: 2
A16: 3 | B16: =IF(塔内機器_計算用シート!Y22=0,"",IF(塔内機器_入力①!$E$42<>"",塔内機器_入力①!$B40,"")) -> 2 | D16: ～ | E16: =IF(塔内機器_計算用シート!Y22=0,"",IF(塔内機器_入力①!$E$42<>"",塔内機器_入力①!$B44,"")) -> 3 | G16: 階 | I16: ： | J16: =IF(塔内機器_計算用シート!Y22=0,"",IF(2>MAX(塔内機器_計算用シート!$E$45:$E$68)-1,"",IFERROR(VLOOKUP(2,塔内機器_計算用シート!$E$45:$K$68,7,FALSE),""))) -> 820【1】
A17: 4
A18: 5 | B18: =IF(塔内機器_計算用シート!Y22=0,"",IF(塔内機器_入力①!$E$46<>"",塔内機器_入力①!$B44,"")) -> 3 | D18: ～ | E18: =IF(塔内機器_計算用シート!Y22=0,"",IF(塔内機器_入力①!$E$46<>"",塔内機器_入力①!$B48,"")) -> 4 | G18: 階 | I18: ： | J18: =IF(塔内機器_計算用シート!Y22=0,"",IF(3>MAX(塔内機器_計算用シート!$E$45:$E$68)-1,"",IFERROR(VLOOKUP(3,塔内機器_計算用シート!$E$45:$K$68,7,FALSE),""))) -> 820【1】
A19: 6
A20: 7 | B20: =IF(塔内機器_計算用シート!Y22=0,"",IF(塔内機器_入力①!$E$50<>"",塔内機器_入力①!$B48,"")) -> 4 | D20: ～ | E20: =IF(塔内機器_計算用シート!Y22=0,"",IF(塔内機器_入力①!$E$50<>"",塔内機器_入力①!$B52,"")) -> 5 | G20: 階 | I20: ： | J20: =IF(塔内機器_計算用シート!Y22=0,"",IF(4>MAX(塔内機器_計算用シート!$E$45:$E$68)-1,"",IFERROR(VLOOKUP(4,塔内機器_計算用シート!$E$45:$K$68,7,FALSE),""))) -> 820【1】
A21: 8
A22: 9 | B22: =IF(塔内機器_入力①!$E$54<>"",塔内機器_入力①!$B52,"") -> 5 | D22: ～ | E22: =IF(塔内機器_計算用シート!Y22=0,"",IF(塔内機器_入力①!$E$54<>"",塔内機器_入力①!$B56,"")) -> 6 | G22: 階 | I22: ： | J22: =IF(塔内機器_計算用シート!Y22=0,"",IF(5>MAX(塔内機器_計算用シート!$E$45:$E$68)-1,"",IFERROR(VLOOKUP(5,塔内機器_計算用シート!$E$45:$K$68,7,FALSE),""))) -> 720【1】
A23: 10
A24: 11 | B24: =IF(塔内機器_計算用シート!Y22=0,"",IF(塔内機器_入力①!$E$58<>"",塔内機器_入力①!$B56,"")) -> 6 | D24: ～ | E24: =IF(塔内機器_計算用シート!Y22=0,"",IF(塔内機器_入力①!$E$58<>"",塔内機器_入力①!$B60,"")) -> 7 | G24: 階 | I24: ： | J24: =IF(塔内機器_計算用シート!Y22=0,"",IF(6>MAX(塔内機器_計算用シート!$E$45:$E$68)-1,"",IFERROR(VLOOKUP(6,塔内機器_計算用シート!$E$45:$K$68,7,FALSE),""))) -> 720【1】
A25: 12
A26: 13 | B26: =IF(塔内機器_計算用シート!Y22=0,"",IF(塔内機器_入力①!$E$62<>"",塔内機器_入力①!$B60,"")) | D26: ～ | E26: =IF(塔内機器_計算用シート!Y22=0,"",IF(塔内機器_入力①!$E$62<>"",塔内機器_入力①!$B64,"")) | G26: 階 | I26: ： | J26: =IF(塔内機器_計算用シート!Y22=0,"",IF(7>MAX(塔内機器_計算用シート!$E$45:$E$68)-1,"",IFERROR(VLOOKUP(7,塔内機器_計算用シート!$E$45:$K$68,7,FALSE),"")))
A27: 14
A28: 15 | B28: =IF(塔内機器_計算用シート!Y22=0,"",IF(塔内機器_入力①!$E$66<>"",塔内機器_入力①!$B64,"")) | D28: ～ | E28: =IF(塔内機器_計算用シート!Y22=0,"",IF(塔内機器_入力①!$E$66<>"",塔内機器_入力①!$K36,"")) | G28: 階 | I28: ： | J28: =IF(塔内機器_計算用シート!Y22=0,"",IF(8>MAX(塔内機器_計算用シート!$E$45:$E$68)-1,"",IFERROR(VLOOKUP(8,塔内機器_計算用シート!$E$45:$K$68,7,FALSE),"")))
A29: 16
A30: 17 | B30: =IF(塔内機器_計算用シート!Y22=0,"",IF(塔内機器_入力①!$N$38<>"",塔内機器_入力①!$K36,"")) | D30: ～ | E30: =IF(塔内機器_計算用シート!Y22=0,"",IF(塔内機器_入力①!$N$38<>"",塔内機器_入力①!$K40,"")) | G30: 階 | I30: ： | J30: =IF(塔内機器_計算用シート!Y22=0,"",IF(9>MAX(塔内機器_計算用シート!$E$45:$E$68)-1,"",IFERROR(VLOOKUP(9,塔内機器_計算用シート!$E$45:$K$68,7,FALSE),"")))
A31: 18
A32: 19 | B32: =IF(塔内機器_計算用シート!Y22=0,"",IF(塔内機器_入力①!$N$42<>"",塔内機器_入力①!$K40,"")) | D32: ～ | E32: =IF(塔内機器_計算用シート!Y22=0,"",IF(塔内機器_入力①!$N$42<>"",塔内機器_入力①!$K44,"")) | G32: 階 | I32: ： | J32: =IF(塔内機器_計算用シート!Y22=0,"",IF(10>MAX(塔内機器_計算用シート!$E$45:$E$68)-1,"",IFERROR(VLOOKUP(10,塔内機器_計算用シート!$E$45:$K$68,7,FALSE),"")))
A33: 20
A34: 21 | B34: =IF(塔内機器_計算用シート!Y22=0,"",IF(塔内機器_入力①!$N$46<>"",塔内機器_入力①!$K44,"")) | D34: ～ | E34: =IF(塔内機器_計算用シート!Y22=0,"",IF(塔内機器_入力①!$N$46<>"",塔内機器_入力①!$K48,"")) | G34: 階 | I34: ： | J34: =IF(塔内機器_計算用シート!Y22=0,"",IF(11>MAX(塔内機器_計算用シート!$E$45:$E$68)-1,"",IFERROR(VLOOKUP(11,塔内機器_計算用シート!$E$45:$K$68,7,FALSE),"")))
A35: 22
A36: 23 | B36: =IF(塔内機器_計算用シート!Y22=0,"",IF(塔内機器_入力①!$N$50<>"",塔内機器_入力①!$K48,"")) | D36: ～ | E36: =IF(塔内機器_計算用シート!Y22=0,"",IF(塔内機器_入力①!$N$50<>"",塔内機器_入力①!$K52,"")) | G36: 階 | I36: ： | J36: =IF(塔内機器_計算用シート!Y22=0,"",IF(12>MAX(塔内機器_計算用シート!$E$45:$E$68)-1,"",IFERROR(VLOOKUP(12,塔内機器_計算用シート!$E$45:$K$68,7,FALSE),"")))
B38: =IF(塔内機器_計算用シート!Y22=0,"",IF(塔内機器_入力①!$N$54<>"",塔内機器_入力①!$K52,"")) | D38: ～ | E38: =IF(塔内機器_計算用シート!Y22=0,"",IF(塔内機器_入力①!$N$54<>"",塔内機器_入力①!$K56,"")) | G38: 階 | I38: ： | J38: =IF(塔内機器_計算用シート!Y22=0,"",IF(13>MAX(塔内機器_計算用シート!$E$45:$E$68)-1,"",IFERROR(VLOOKUP(13,塔内機器_計算用シート!$E$45:$K$68,7,FALSE),"")))
B40: =IF(塔内機器_計算用シート!Y22=0,"",IF(塔内機器_入力①!$N$58<>"",塔内機器_入力①!$K56,"")) | D40: ～ | E40: =IF(塔内機器_計算用シート!Y22=0,"",IF(塔内機器_入力①!$N$58<>"",塔内機器_入力①!$K60,"")) | G40: 階 | I40: ： | J40: =IF(塔内機器_計算用シート!Y22=0,"",IF(14>MAX(塔内機器_計算用シート!$E$45:$E$68)-1,"",IFERROR(VLOOKUP(14,塔内機器_計算用シート!$E$45:$K$68,7,FALSE),"")))
B42: =IF(塔内機器_計算用シート!Y22=0,"",IF(塔内機器_入力①!$N$62<>"",塔内機器_入力①!$K60,"")) | D42: ～ | E42: =IF(塔内機器_計算用シート!Y22=0,"",IF(塔内機器_入力①!$N$62<>"",塔内機器_入力①!$K64,"")) | G42: 階 | I42: ： | J42: =IF(塔内機器_計算用シート!Y22=0,"",IF(15>MAX(塔内機器_計算用シート!$E$45:$E$68)-1,"",IFERROR(VLOOKUP(15,塔内機器_計算用シート!$E$45:$K$68,7,FALSE),"")))
B44: =IF(塔内機器_計算用シート!Y22=0,"",IF(塔内機器_入力①!$N$66<>"",塔内機器_入力①!$K64,"")) | D44: ～ | E44: =IF(塔内機器_計算用シート!Y22=0,"",IF(塔内機器_入力①!$N$66<>"",塔内機器_入力①!$T36,"")) | G44: 階 | I44: ： | J44: =IF(塔内機器_計算用シート!Y22=0,"",IF(16>MAX(塔内機器_計算用シート!$E$45:$E$68)-1,"",IFERROR(VLOOKUP(16,塔内機器_計算用シート!$E$45:$K$68,7,FALSE),"")))
B46: =IF(塔内機器_計算用シート!Y22=0,"",IF(塔内機器_入力①!$W$38<>"",塔内機器_入力①!$T36,"")) | D46: ～ | E46: =IF(塔内機器_計算用シート!Y22=0,"",IF(塔内機器_入力①!$W$38<>"",塔内機器_入力①!$T40,"")) | G46: 階 | I46: ： | J46: =IF(塔内機器_計算用シート!Y22=0,"",IF(17>MAX(塔内機器_計算用シート!$E$45:$E$68)-1,"",IFERROR(VLOOKUP(17,塔内機器_計算用シート!$E$45:$K$68,7,FALSE),"")))
B48: =IF(塔内機器_計算用シート!Y22=0,"",IF(塔内機器_入力①!$W$42<>"",塔内機器_入力①!$T40,"")) | D48: ～ | E48: =IF(塔内機器_計算用シート!Y22=0,"",IF(塔内機器_入力①!$W$42<>"",塔内機器_入力①!$T44,"")) | G48: 階 | I48: ： | J48: =IF(塔内機器_計算用シート!Y22=0,"",IF(18>MAX(塔内機器_計算用シート!$E$45:$E$68)-1,"",IFERROR(VLOOKUP(18,塔内機器_計算用シート!$E$45:$K$68,7,FALSE),"")))
B50: =IF(塔内機器_計算用シート!Y22=0,"",IF(塔内機器_入力①!$W$46<>"",塔内機器_入力①!$T44,"")) | D50: ～ | E50: =IF(塔内機器_計算用シート!Y22=0,"",IF(塔内機器_入力①!$W$46<>"",塔内機器_入力①!$T48,"")) | G50: 階 | I50: ： | J50: =IF(塔内機器_計算用シート!Y22=0,"",IF(19>MAX(塔内機器_計算用シート!$E$45:$E$68)-1,"",IFERROR(VLOOKUP(19,塔内機器_計算用シート!$E$45:$K$68,7,FALSE),"")))
B52: =IF(塔内機器_計算用シート!Y22=0,"",IF(塔内機器_入力①!$W$50<>"",塔内機器_入力①!$T48,"")) | D52: ～ | E52: =IF(塔内機器_計算用シート!Y22=0,"",IF(塔内機器_入力①!$W$50<>"",塔内機器_入力①!$T52,"")) | G52: 階 | I52: ： | J52: =IF(塔内機器_計算用シート!Y22=0,"",IF(20>MAX(塔内機器_計算用シート!$E$45:$E$68)-1,"",IFERROR(VLOOKUP(20,塔内機器_計算用シート!$E$45:$K$68,7,FALSE),"")))
B54: =IF(塔内機器_計算用シート!Y22=0,"",IF(塔内機器_入力①!$W$54<>"",塔内機器_入力①!$T52,"")) | D54: ～ | E54: =IF(塔内機器_計算用シート!Y22=0,"",IF(塔内機器_入力①!$W$54<>"",塔内機器_入力①!$T56,"")) | G54: 階 | I54: ： | J54: =IF(塔内機器_計算用シート!Y22=0,"",IF(21>MAX(塔内機器_計算用シート!$E$45:$E$68)-1,"",IFERROR(VLOOKUP(21,塔内機器_計算用シート!$E$45:$K$68,7,FALSE),"")))
B56: =IF(塔内機器_計算用シート!Y22=0,"",IF(塔内機器_入力①!$W$58<>"",塔内機器_入力①!$T56,"")) | D56: ～ | E56: =IF(塔内機器_計算用シート!Y22=0,"",IF(塔内機器_入力①!$W$58<>"",塔内機器_入力①!$T60,"")) | G56: 階 | I56: ： | J56: =IF(塔内機器_計算用シート!Y22=0,"",IF(22>MAX(塔内機器_計算用シート!$E$45:$E$68)-1,"",IFERROR(VLOOKUP(22,塔内機器_計算用シート!$E$45:$K$68,7,FALSE),"")))
B58: =IF(塔内機器_計算用シート!Y22=0,"",IF(塔内機器_入力①!$W$62<>"",塔内機器_入力①!$T60,"")) | D58: ～ | E58: =IF(塔内機器_計算用シート!Y22=0,"",IF(塔内機器_入力①!$W$62<>"",塔内機器_入力①!$T64,"")) | G58: 階 | I58: ： | J58: =IF(塔内機器_計算用シート!Y22=0,"",IF(23>MAX(塔内機器_計算用シート!$E$45:$E$68)-1,"",IFERROR(VLOOKUP(23,塔内機器_計算用シート!$E$45:$K$68,7,FALSE),"")))
K70: 目次へ戻る
B75: =CONCATENATE(塔内機器_計算用シート!AH42," ",塔内機器_計算用シート!Y23) -> v4 参照範囲内（設計妥当性は要照合）

Sheet 塔内機器_計算用シート
B2: ■ガバナロープ振れ止め取付高さ | H2: ■各階高さ | R2: ■フィッシャープレート組合せ
I3: 検索用階高累計 | L3: 検索用累計＋ピット | R3: 仕様（型式+OP+遮煙）
B4: 1 | C4: つ目 | D4: =IF($AH$40=0,"",IF(B4>$AH$37,"",(塔内機器_入力①!B20/($AH$37+1))*B4)) -> 12235 | E4: ㎜ | H4: № | I4: 各階高さ(mm) | O4: 階 | R4: =CONCATENATE(塔内機器_入力①!B14,塔内機器_入力①!P14,塔内機器_入力①!P26) -> UA-25TP900有 | X4: 階床キー一致件数 | Y4: =IF(帳票基本入力!C5="",0,COUNTIF(塔内機器_入力①_DB!$C$2:$C$937,帳票基本入力!C5)) -> 1
B5: 2 | C5: つ目 | D5: =IF($AH$40=0,"",IF(B5>$AH$37,"",(塔内機器_入力①!B20/($AH$37+1))*B5)) | E5: ㎜ | H5: 1 | I5: 0 | L5: =IF(Y7=1,塔内機器_入力①!B26,0) -> 1300 | O5: ピット | P5: ～ | Q5: =塔内機器_入力①!B36 -> 1 | X5: 有効な階床数 | Y5: =SUM(AD45:AD68) -> 7
B6: 3 | C6: つ目 | D6: =IF($AH$40=0,"",IF(B6>$AH$37,"",(塔内機器_入力①!B20/($AH$37+1))*B6)) | E6: ㎜ | H6: 2 | I6: =IF(Q6="",1000000+H6,SUM($C$45:C45)) -> 3745 | L6: =IF(Q6="",1000000+H6,I6+$L$5) -> 5045 | O6: =Q5 -> 1 | P6: ～ | Q6: =塔内機器_入力①!B40 -> 2 | R6: ■中間振れ止め/テールコードサポート仕様 | X6: 機種グループ | Y6: =IFERROR(VLOOKUP(R4,塔内機器_出力②_DB!$M$4:$N$23,2,FALSE),0) -> 104
B7: 4 | C7: つ目 | D7: =IF($AH$40=0,"",IF(B7>$AH$37,"",(塔内機器_入力①!B20/($AH$37+1))*B7)) | E7: ㎜ | H7: 3 | I7: =IF(Q7="",1000000+H7,SUM($C$45:C46)) -> 7045 | L7: =IF(Q7="",1000000+H7,I7+$L$5) -> 8345 | O7: =Q6 -> 2 | P7: ～ | Q7: =塔内機器_入力①!B44 -> 3 | R7: =帳票基本入力!C8 -> 後落ち | X7: 主要寸法の入力 | Y7: =IF(AND(IFERROR(IF(AND(COUNT(塔内機器_入力①!B20)=1,塔内機器_入力①!B20>0,塔内機器_入力①!B20<=$Y$20,塔内機器_入力①!B20=ROUNDDOWN(塔内機器_入力①!B20,0)),1,0),0)=1,IFERROR(IF(AND(COUNT(塔内機器_入力①!P20)=1,塔内機器_入力①!P20>0,塔内機器_入力①!P20<=$Y$20,塔内機器_入力①!P20=ROUNDDOWN(塔内機器_入力①!P20,0)),1,0),0)=1,IFERROR(IF(AND(COUNT(塔内機器_入力①!B26)=1,塔内機器_入力①!B26>=0,塔内機器_入力①!B26<=$Y$20,塔内機器_入力①!B26=ROUNDDOWN(塔内機器_入力①!B26,0)),1,0),0)=1),1,0) -> 1
B8: 5 | C8: つ目 | D8: =IF($AH$40=0,"",IF(B8>$AH$37,"",(塔内機器_入力①!B20/($AH$37+1))*B8)) | E8: ㎜ | H8: 4 | I8: =IF(Q8="",1000000+H8,SUM($C$45:C47)) -> 10345 | L8: =IF(Q8="",1000000+H8,I8+$L$5) -> 11645 | O8: =Q7 -> 3 | P8: ～ | Q8: =塔内機器_入力①!B48 -> 4 | R8: =IF(AND(R7="後落ち",U32="〇"),1,IF(AND(R7="後落ち",U33="〇"),2,IF(AND(R7="後落ち",OR(U34="〇",U35="〇",U36="〇")),3,""))) -> 3 | X8: 階高入力の不備件数 | Y8: =SUM(AA45:AA68) -> 0
B9: 6 | C9: つ目 | D9: =IF($AH$40=0,"",IF(B9>$AH$37,"",(塔内機器_入力①!B20/($AH$37+1))*B9)) | E9: ㎜ | H9: 5 | I9: =IF(Q9="",1000000+H9,SUM($C$45:C48)) -> 13645 | L9: =IF(Q9="",1000000+H9,I9+$L$5) -> 14945 | O9: =Q8 -> 4 | P9: ～ | Q9: =塔内機器_入力①!B52 -> 5 | R9: =IF(R8="","",IF(R8=1,"P-6",IF(R8=2,"P-9","P-11～P-15"))) -> P-11～P-15 | X9: 未使用欄の残値件数 | Y9: =SUM(AB45:AB68) -> 0
H10: 6 | I10: =IF(Q10="",1000000+H10,SUM($C$45:C49)) -> 16895 | L10: =IF(Q10="",1000000+H10,I10+$L$5) -> 18195 | O10: =Q9 -> 5 | P10: ～ | Q10: =塔内機器_入力①!B56 -> 6 | X10: 行程と階高合計の一致 | Y10: =IFERROR(IF(塔内機器_入力①!P20=Y12,1,0),0) -> 1
H11: 7 | I11: =IF(Q11="",1000000+H11,SUM($C$45:C50)) -> 20145 | L11: =IF(Q11="",1000000+H11,I11+$L$5) -> 21445 | O11: =Q10 -> 6 | P11: ～ | Q11: =塔内機器_入力①!B60 -> 7 | X11: 全高・行程・ピットの整合 | Y11: =IFERROR(IF(塔内機器_入力①!B20>塔内機器_入力①!P20+塔内機器_入力①!B26,1,0),0) -> 1
H12: 8 | I12: =IF(Q12="",1000000+H12,SUM($C$45:C51)) -> 1000008 | L12: =IF(Q12="",1000000+H12,I12+$L$5) -> 1000008 | O12: =Q11 -> 7 | P12: ～ | Q12: =塔内機器_入力①!B64 | X12: 有効な階高の合計 mm | Y12: =SUM(C45:C68) -> 20145
H13: 9 | I13: =IF(Q13="",1000000+H13,SUM($C$45:C52)) -> 1000009 | L13: =IF(Q13="",1000000+H13,I13+$L$5) -> 1000009 | O13: =Q12 | P13: ～ | Q13: =塔内機器_入力①!K36 | X13: 制御盤距離の入力 | Y13: =IFERROR(IF(AND(COUNT(帳票基本入力!C9)=1,帳票基本入力!C9>0,帳票基本入力!C9<=塔内機器_入力①!B20,帳票基本入力!C9=ROUNDDOWN(帳票基本入力!C9,0)),1,0),0) -> 1
H14: 10 | I14: =IF(Q14="",1000000+H14,SUM($C$45:C53)) -> 1000010 | L14: =IF(Q14="",1000000+H14,I14+$L$5) -> 1000010 | O14: =Q13 | P14: ～ | Q14: =塔内機器_入力①!K40 | X14: 仕様の入力 | Y14: =IF(AND(OR(帳票基本入力!C7="Cwtｾﾌﾃｨ付",帳票基本入力!C7="Cwtｾﾌﾃｨなし"),OR(R7="後落ち",R7="横落ち"),OR(塔内機器_入力①!P26="有",塔内機器_入力①!P26="無"),COUNT(塔内機器_入力①!P14)=1,OR(塔内機器_入力①!B14="UA-25TP",塔内機器_入力①!B14="UAE-25T",塔内機器_入力①!B14="UA-25TR",塔内機器_入力①!B14="UA-25TB"),COUNTIF(U32:U36,"〇")=1,Y6>0),1,0) -> 1
H15: 11 | I15: =IF(Q15="",1000000+H15,SUM($C$45:C54)) -> 1000011 | L15: =IF(Q15="",1000000+H15,I15+$L$5) -> 1000011 | O15: =Q14 | P15: ～ | Q15: =塔内機器_入力①!K44 | X15: 入力条件の成立 1=成立 | Y15: =IF(AND(Y4=1,Y5>=2,Y7=1,Y8=0,Y9=0,Y10=1,Y11=1,Y13=1,Y14=1,Y21=0,Y27=1),1,0) -> 1
H16: 12 | I16: =IF(Q16="",1000000+H16,SUM($C$45:C55)) -> 1000012 | L16: =IF(Q16="",1000000+H16,I16+$L$5) -> 1000012 | O16: =Q15 | P16: ～ | Q16: =塔内機器_入力①!K48 | X16: 入力状態 | Y16: =IF(Y4<>1,"要確認：階床名が空欄・未登録・重複",IF(Y5<2,"要確認：階床は2階以上必要",IF(Y21>0,"要確認：階床DBの空き・重複を修正",IF(Y7=0,"要確認：全高・行程・ピットは範囲内の整数",IF(Y8>0,"要確認：使用する階高は正の整数",IF(Y9>0,"要確認：未使用の階高欄を空欄にする",IF(Y10=0,"要確認：行程と有効な階高合計が不一致",IF(Y11=0,"要確認：全高は行程とピットの合計より大きく",IF(Y13=0,"要確認：制御盤距離は正の整数・全高以下",IF(Y14=0,"要確認：機種・OP・遮煙・基本仕様を確認",IF(Y27=0,"要確認：最上部取付位置が配置可能範囲外","入力条件成立"))))))))))) -> 入力条件成立
H17: 13 | I17: =IF(Q17="",1000000+H17,SUM($C$45:C56)) -> 1000013 | L17: =IF(Q17="",1000000+H17,I17+$L$5) -> 1000013 | O17: =Q16 | P17: ～ | Q17: =塔内機器_入力①!K52 | X17: 部品DBの不備件数 | Y17: =SUM(AJ45:AJ68) -> 0
H18: 14 | I18: =IF(Q18="",1000000+H18,SUM($C$45:C57)) -> 1000014 | L18: =IF(Q18="",1000000+H18,I18+$L$5) -> 1000014 | O18: =Q17 | P18: ～ | Q18: =塔内機器_入力①!K56 | X18: 部品出力状態 | Y18: =IF(Y15=0,"入力修正後に判定",IF(Y17>0,"部品出力停止：未確認・範囲外のDBあり","参照範囲内（設計妥当性は要照合）")) -> 参照範囲内（設計妥当性は要照合）
H19: 15 | I19: =IF(Q19="",1000000+H19,SUM($C$45:C58)) -> 1000015 | L19: =IF(Q19="",1000000+H19,I19+$L$5) -> 1000015 | O19: =Q18 | P19: ～ | Q19: =塔内機器_入力①!K60 | X19: ガバナDB上限 mm | Y19: 90000
B20: ■テールコード最上部ブラケット | H20: 16 | I20: =IF(Q20="",1000000+H20,SUM($C$45:C59)) -> 1000016 | L20: =IF(Q20="",1000000+H20,I20+$L$5) -> 1000016 | O20: =Q19 | P20: ～ | Q20: =塔内機器_入力①!K64 | X20: サポートDB上限 mm | Y20: =MAX(O32:O39) -> 90000
D21: =IF(Y15=0,"",塔内機器_入力①!P20-帳票基本入力!C9-$Y$35) -> 16770 | H21: 17 | I21: =IF(Q21="",1000000+H21,SUM($C$45:C60)) -> 1000017 | L21: =IF(Q21="",1000000+H21,I21+$L$5) -> 1000017 | O21: =Q20 | P21: ～ | Q21: =塔内機器_入力①!T36 | X21: 階床順序・重複の不備 | Y21: =SUM(AC45:AC68) -> 0
D22: =IF(Y15=0,"",Y26) -> 21370 | H22: 18 | I22: =IF(Q22="",1000000+H22,SUM($C$45:C61)) -> 1000018 | L22: =IF(Q22="",1000000+H22,I22+$L$5) -> 1000018 | O22: =Q21 | P22: ～ | Q22: =塔内機器_入力①!T40 | X22: 部品DB出力可 1=可 | Y22: =IF(AND(Y15=1,Y17=0),1,0) -> 1
H23: 19 | I23: =IF(Q23="",1000000+H23,SUM($C$45:C62)) -> 1000019 | L23: =IF(Q23="",1000000+H23,I23+$L$5) -> 1000019 | O23: =Q22 | P23: ～ | Q23: =塔内機器_入力①!T44 | X23: 全体の状態 | Y23: =IF(Y15=0,Y16,IF(AH41<>"",AH41,IF(AH36<>"",AH36,Y18))) -> 参照範囲内（設計妥当性は要照合）
H24: 20 | I24: =IF(Q24="",1000000+H24,SUM($C$45:C63)) -> 1000020 | L24: =IF(Q24="",1000000+H24,I24+$L$5) -> 1000020 | O24: =Q23 | P24: ～ | Q24: =塔内機器_入力①!T48 | X24: ガバナ個数 | Y24: =IF(Y7=0,0,IF(塔内機器_入力①!B20>Y19,0,VLOOKUP(塔内機器_入力①!B20,塔内機器_出力①_DB!B6:E11,4,TRUE))) -> 1
H25: 21 | I25: =IF(Q25="",1000000+H25,SUM($C$45:C64)) -> 1000021 | L25: =IF(Q25="",1000000+H25,I25+$L$5) -> 1000021 | O25: =Q24 | P25: ～ | Q25: =塔内機器_入力①!T52 | X25: サポート個数 | Y25: =IF(Y7=0,0,VLOOKUP(塔内機器_入力①!B20,$L$32:$Q$39,6,TRUE)) -> 2
H26: 22 | I26: =IF(Q26="",1000000+H26,SUM($C$45:C65)) -> 1000022 | L26: =IF(Q26="",1000000+H26,I26+$L$5) -> 1000022 | O26: =Q25 | P26: ～ | Q26: =塔内機器_入力①!T56 | X26: 最上部取付位置 mm | Y26: =IF(OR(Y7=0,Y13=0),0,IF(R8="",塔内機器_入力①!P20-帳票基本入力!C9-$Y$35,塔内機器_入力①!P20+VLOOKUP(R9,塔内機器_出力②_DB!$Q$4:$R$6,2,FALSE))) -> 21370
H27: 23 | I27: =IF(Q27="",1000000+H27,SUM($C$45:C66)) -> 1000023 | L27: =IF(Q27="",1000000+H27,I27+$L$5) -> 1000023 | O27: =Q26 | P27: ～ | Q27: =塔内機器_入力①!T60 | X27: 取付位置の整合 | Y27: =IFERROR(IF(AND(Y26>=塔内機器_入力①!P20/2+$Y$34,Y26<=塔内機器_入力①!B20-塔内機器_入力①!B26),1,0),0) -> 1
H28: 24 | I28: =IF(Q28="",1000000+H28,SUM($C$45:C67)) -> 1000024 | L28: =IF(Q28="",1000000+H28,I28+$L$5) -> 1000024 | O28: =Q27 | P28: ～ | Q28: =塔内機器_入力①!T64 | X28: 推定行の確認記録 1=成立 | Y28: =IFERROR(VLOOKUP(Y6,塔内機器_出力②_DB!$T$4:$AA$23,8,FALSE),0) -> 0
B30: ■ケーブルサポート・テールコードサポートブラ取付高さ | L30: ■ケーブルサポートブラ手配員数表 | X30: 空階の検索キーは1,000,000超。実高さの合計はY12。
B31: 1 | C31: つ目 | D31: =IF($Y$39=0,"",AH32) -> 10572.5 | E31: mm | L31: 全高 TH | Q31: 員数 | S31: 機種(P型) | U31: 判定 | X31: 出力② 共通条件（元の計算規則）
B32: 2 | C32: つ目 | D32: =IF($Y$39=0,"",IF(B32>$Y$37,"",IF(B32=$Y$37,$D$22,$D$31+(B32-1)*$H$34))) -> 15971.5 | E32: mm | H32: ピッチ | L32: 0 | N32: ~ | O32: 15000 | Q32: 1 | S32: P-6 | U32: =IF(OR(MID(帳票基本入力!C6,3,4)="P-6-",RIGHT(帳票基本入力!C6,3)="P-6"),"〇","") | X32: テール用ブラ増員の行程上限 mm | Y32: 40000 | AB32: 出力② 開始位置S mm | AH32: =IF(Y15=0,"",塔内機器_入力①!P20/2+$Y$34) -> 10572.5
B33: 3 | C33: つ目 | D33: =IF($Y$39=0,"",IF(B33>$Y$37,"",IF(B33=$Y$37,$D$22,$D$31+(B33-1)*$H$34))) -> 21370 | E33: mm | H33: =IF($Y$39=0,"",(D22-D31)/($Y$37-1)) -> 5398.75 | L33: 15001 | N33: ~ | O33: 25000 | Q33: 2 | S33: P-9 | U33: =IF(OR(MID(帳票基本入力!C6,3,4)="P-9-",RIGHT(帳票基本入力!C6,3)="P-9"),"〇","") | X33: Lタイプの行程上限 mm | Y33: 80000 | AB33: 出力② 個数成立 1=可 | AH33: =IF(Y15=0,0,IF(AND(Y37>=2,Y37<=$Y$40,Y37=ROUNDDOWN(Y37,0)),1,0)) -> 1
B34: 4 | C34: つ目 | D34: =IF($Y$39=0,"",IF(B34>$Y$37,"",IF(B34=$Y$37,$D$22,$D$31+(B34-1)*$H$34))) | E34: mm | H34: =IF($Y$39=0,"",AH34) -> 5399 | L34: 25001 | N34: ~ | O34: 40000 | Q34: 4 | S34: P-11 | U34: =IF(OR(MID(帳票基本入力!C6,3,5)="P-11-",RIGHT(帳票基本入力!C6,4)="P-11"),"〇","") | X34: 最初の位置への加算 mm | Y34: 500 | AB34: 出力② 切上げ間隔P mm | AH34: =IF(AH33=0,"",ROUNDUP((Y26-AH32)/(Y37-1),0)) -> 5399
B35: 5 | C35: つ目 | D35: =IF($Y$39=0,"",IF(B35>$Y$37,"",IF(B35=$Y$37,$D$22,$D$31+(B35-1)*$H$34))) | E35: mm | L35: 40001 | N35: ~ | O35: 50000 | Q35: 5 | S35: P-13 | U35: =IF(OR(MID(帳票基本入力!C6,3,5)="P-13-",RIGHT(帳票基本入力!C6,4)="P-13"),"〇","") -> 〇 | X35: 横落ち制御盤下端補正 mm | Y35: 295 | AB35: 出力② 最終間隔 mm | AH35: =IF(AH33=0,"",Y26-(AH32+(Y37-2)*AH34)) -> 5398.5
B36: 6 | C36: つ目 | D36: =IF($Y$39=0,"",IF(B36>$Y$37,"",IF(B36=$Y$37,$D$22,$D$31+(B36-1)*$H$34))) | E36: mm | L36: 50001 | N36: ~ | O36: 60000 | Q36: 5 | S36: P-15 | U36: =IF(OR(MID(帳票基本入力!C6,3,5)="P-15-",RIGHT(帳票基本入力!C6,4)="P-15"),"〇","") | X36: テールコードサポートブラ個数 | Y36: =IF(Y15=0,"",IF(塔内機器_入力①!P20<=$Y$32,1,2)) -> 1 | AB36: 出力② 個別警告 | AH36: =IF(Y15=0,Y16,IF(AH33=0,"要確認：出力②の取付箇所数が範囲外",IF(Y39=0,"要確認：出力②の取付間隔が0以下","")))
B37: 7 | C37: つ目 | D37: =IF($Y$39=0,"",IF(B37>$Y$37,"",IF(B37=$Y$37,$D$22,$D$31+(B37-1)*$H$34))) | E37: mm | L37: 60001 | N37: ~ | O37: 70000 | Q37: 5 | X37: 合計取付箇所数 | Y37: =IF(Y15=0,"",Y25+Y36) -> 3 | AB37: 出力① 実効ガバナ個数 | AH37: =IF(Y15=0,0,IF(帳票基本入力!C7="Cwtｾﾌﾃｨなし",0,Y24)) -> 1
B38: 8 | C38: つ目 | D38: =IF($Y$39=0,"",IF(B38>$Y$37,"",IF(B38=$Y$37,$D$22,$D$31+(B38-1)*$H$34))) | E38: mm | L38: 70001 | N38: ~ | O38: 80000 | Q38: 6 | X38: テールコードタイプ | Y38: =IF(Y15=0,"",IF(塔内機器_入力①!P20<=$Y$33,"Lタイプ","Hタイプ")) -> Lタイプ | AB38: 出力① 最初の位置 mm | AH38: =IF(Y15=0,"",IF(OR(AH37<=0,AH37>6,AH37<>ROUNDDOWN(AH37,0)),"",塔内機器_入力①!B20/(AH37+1))) -> 12235
B39: 9 | C39: つ目 | D39: =IF($Y$39=0,"",IF(B39>$Y$37,"",IF(B39=$Y$37,$D$22,$D$31+(B39-1)*$H$34))) | E39: mm | L39: 80001 | N39: ~ | O39: 90000 | Q39: 7 | X39: 取付行表示可 1=可 | Y39: =IF(AH33=0,0,IF(AND(AH34>0,AH35>0),1,0)) -> 1 | AB39: 出力① 最後の位置 mm | AH39: =IF(AH38="","",AH38*AH37) -> 12235
X40: 帳票の最大取付箇所数 | Y40: 9 | AB40: 出力① 配置成立 1=可 | AH40: =IF(Y15=0,0,IF(AH37=0,1,IF(AH38="",0,IF(AND(AH38>=L5,AH39<=塔内機器_入力①!B20),1,0)))) -> 1
AB41: 出力① 個別警告 | AH41: =IF(Y15=0,Y16,IF(AH37=0,"",IF(AH38="","要確認：出力①の取付箇所数が範囲外",IF(AH40=0,"要確認：出力①の位置が最下階FL未満",""))))
AB42: 帳票共通版 | AH42: v4
...

Sheet 塔内機器_入力①_DB
A1: No. | B1: 区分 | C1: 階床名 | D1: 1(最下階) | E1: 2 | F1: 3 | G1: 4 | H1: 5 | I1: 6 | J1: 7 | K1: 8 | L1: 9 | M1: 10 | N1: 11 | O1: 12 | P1: 13 | Q1: 14 | R1: 15 | S1: 16 | T1: 17 | U1: 18 | V1: 19 | W1: 20 | X1: 21 | Y1: 22 | Z1: 23 | AA1: 24 | AB1: 補完根拠 | AC1: 確認区分
A2: 1 | B2: 既存 | C2: B5-B2,B1N,1 | D2: B5 | E2: B4 | F2: B3 | G2: B2 | H2: B1N | I2: 1 | AB2: QR収録 | AC2: 原データ
A3: 2 | B3: 既存 | C3: B5-B1,1 | D3: B5 | E3: B4 | F3: B3 | G3: B2 | H3: B1 | I3: 1 | AB3: QR収録 | AC3: 原データ
A4: 3 | B4: 既存 | C4: B5,B3,B2 | D4: B5 | E4: B3 | F4: B2 | AB4: QR収録 | AC4: 原データ
A5: 4 | B5: 既存 | C5: B4,B3N,B2N,B1U | D5: B4 | E5: B3N | F5: B2N | G5: B1U | AB5: QR収録 | AC5: 原データ
A6: 5 | B6: 既存 | C6: B4-B3 | D6: B4 | E6: B3 | AB6: QR収録 | AC6: 原データ
A7: 6 | B7: 既存 | C7: B4-B1 | D7: B4 | E7: B3 | F7: B2 | G7: B1 | AB7: QR収録 | AC7: 原データ
A8: 7 | B8: 既存 | C8: B4,B3,B2,B1,1 | D8: B4 | E8: B3 | F8: B2 | G8: B1 | H8: 1 | AB8: QR収録 | AC8: 原データ
A9: 8 | B9: 既存 | C9: B4-B1,1 | D9: B4 | E9: B3 | F9: B2 | G9: B1 | H9: 1 | AB9: QR収録 | AC9: 原データ
A10: 9 | B10: 既存 | C10: B4-B3,B1,1 | D10: B4 | E10: B3 | F10: B1 | G10: 1 | AB10: QR収録 | AC10: 原データ
A11: 10 | B11: 既存 | C11: B3,B2N-B1N,1-2 | D11: B3 | E11: B2N | F11: B1N | G11: 1 | H11: 2 | AB11: QR収録 | AC11: 原データ
A12: 11 | B12: 既存 | C12: B3,B2N,B1,1 | D12: B3 | E12: B2N | F12: B1 | G12: 1 | AB12: QR収録 | AC12: 原データ
A13: 12 | B13: 既存 | C13: B3,B2 | D13: B3 | E13: B2 | AB13: QR収録 | AC13: 原データ
A14: 13 | B14: 既存 | C14: B3-B2 | D14: B3 | E14: B2 | AB14: QR収録 | AC14: 原データ
A15: 14 | B15: 既存 | C15: B3,B2,B1N,1 | D15: B3 | E15: B2 | F15: B1N | G15: 1 | AB15: QR収録 | AC15: 原データ
A16: 15 | B16: 既存 | C16: B3-B2,B1N,1,2N-4N,5- | D16: B3 | E16: B2 | F16: B1N | G16: 1 | H16: 2N | I16: 3N | J16: 4N | K16: 5- | AB16: QR収録 | AC16: 原データ
A17: 16 | B17: 既存 | C17: B3,B2,B1 | D17: B3 | E17: B2 | F17: B1 | AB17: QR収録 | AC17: 原データ
A18: 17 | B18: 既存 | C18: B3-B1 | D18: B3 | E18: B2 | F18: B1 | AB18: QR収録 | AC18: 原データ
A19: 18 | B19: 既存 | C19: B3,B2,B1,B1U,1-5,5U | D19: B3 | E19: B2 | F19: B1 | G19: B1U | H19: 1 | I19: 2 | J19: 3 | K19: 4 | L19: 5 | M19: 5U | AB19: QR収録 | AC19: 原データ
A20: 19 | B20: 既存 | C20: B3,B2,B1,1 | D20: B3 | E20: B2 | F20: B1 | G20: 1 | AB20: QR収録 | AC20: 原データ
A21: 20 | B21: 既存 | C21: B3-B1,1 | D21: B3 | E21: B2 | F21: B1 | G21: 1 | AB21: QR収録 | AC21: 原データ
A22: 21 | B22: 既存 | C22: B3-B1,1-2 | D22: B3 | E22: B2 | F22: B1 | G22: 1 | H22: 2 | AB22: QR収録 | AC22: 原データ
A23: 22 | B23: 既存 | C23: B3-B1,1-3 | D23: B3 | E23: B2 | F23: B1 | G23: 1 | H23: 2 | I23: 3 | AB23: QR収録 | AC23: 原データ
A24: 23 | B24: 既存 | C24: B3,B2,B1,1-3,4N,5,6 | D24: B3 | E24: B2 | F24: B1 | G24: 1 | H24: 2 | I24: 3 | J24: 4N | K24: 5 | L24: 6 | AB24: QR収録 | AC24: 原データ
A25: 24 | B25: 既存 | C25: B3-B1,1-4 | D25: B3 | E25: B2 | F25: B1 | G25: 1 | H25: 2 | I25: 3 | J25: 4 | AB25: QR収録 | AC25: 原データ
A26: 25 | B26: 既存 | C26: B3-B1,1-5 | D26: B3 | E26: B2 | F26: B1 | G26: 1 | H26: 2 | I26: 3 | J26: 4 | K26: 5 | AB26: QR収録 | AC26: 原データ
A27: 26 | B27: 既存 | C27: B3,B2,B1,1-6 | D27: B3 | E27: B2 | F27: B1 | G27: 1 | H27: 2 | I27: 3 | J27: 4 | K27: 5 | L27: 6 | AB27: QR収録 | AC27: 原データ
A28: 27 | B28: 既存 | C28: B3-B1,1-13 | D28: B3 | E28: B2 | F28: B1 | G28: 1 | H28: 2 | I28: 3 | J28: 4 | K28: 5 | L28: 6 | M28: 7 | N28: 8 | O28: 9 | P28: 10 | Q28: 11 | R28: 12 | S28: 13 | AB28: QR収録 | AC28: 原データ
A29: 28 | B29: 既存 | C29: B3,B2,B1,1-14 | D29: B3 | E29: B2 | F29: B1 | G29: 1 | H29: 2 | I29: 3 | J29: 4 | K29: 5 | L29: 6 | M29: 7 | N29: 8 | O29: 9 | P29: 10 | Q29: 11 | R29: 12 | S29: 13 | T29: 14 | AB29: QR収録 | AC29: 原データ
A30: 29 | B30: 既存 | C30: B3-B1,1-3,R | D30: B3 | E30: B2 | F30: B1 | G30: 1 | H30: 2 | I30: 3 | J30: R | AB30: QR収録 | AC30: 原データ
A31: 30 | B31: 既存 | C31: B3,B2,1 | D31: B3 | E31: B2 | F31: 1 | AB31: QR収録 | AC31: 原データ
A32: 31 | B32: 既存 | C32: B3,B2U,B1 | D32: B3 | E32: B2U | F32: B1 | AB32: QR収録 | AC32: 原データ
A33: 32 | B33: 既存 | C33: B3,B2U,B1U,1U | D33: B3 | E33: B2U | F33: B1U | G33: 1U | AB33: QR収録 | AC33: 原データ
A34: 33 | B34: 既存 | C34: B3,B1N,1 | D34: B3 | E34: B1N | F34: 1 | AB34: QR収録 | AC34: 原データ
A35: 34 | B35: 既存 | C35: B3,B1 | D35: B3 | E35: B1 | AB35: QR収録 | AC35: 原データ
A36: 35 | B36: 既存 | C36: B3,B1,1 | D36: B3 | E36: B1 | F36: 1 | AB36: QR収録 | AC36: 原データ
A37: 36 | B37: 既存 | C37: B3,1 | D37: B3 | E37: 1 | AB37: QR収録 | AC37: 原データ
A38: 37 | B38: 既存 | C38: B2,B1N,1 | D38: B2 | E38: B1N | F38: 1 | AB38: QR収録 | AC38: 原データ
A39: 38 | B39: 既存 | C39: B2,B1N,1,2N,3-6 | D39: B2 | E39: B1N | F39: 1 | G39: 2N | H39: 3 | I39: 4 | J39: 5 | K39: 6 | AB39: QR収録 | AC39: 原データ
A40: 39 | B40: 既存 | C40: B2,B1N,1-2 | D40: B2 | E40: B1N | F40: 1 | G40: 2 | AB40: QR収録 | AC40: 原データ
...

Sheet 塔内機器_出力①_DB
B3: ■ガバナ振れ止め(CWT側ガバナ用)員数ＤＢ
B4: 対象：UA-25T,WTSF付
B5: 全高 | E5: 員数
B6: 0 | C6: ～ | D6: 10000 | E6: 0
B7: 10001 | C7: ～ | D7: 30000 | E7: 1
B8: 30001 | C8: ～ | D8: 45000 | E8: 2
B9: 45001 | C9: ～ | D9: 60000 | E9: 3
B10: 60001 | C10: ～ | D10: 75000 | E10: 4
B11: 75001 | C11: ～ | D11: 90000 | E11: 5

Sheet 塔内機器_出力②_DB
B2: ■フェッシャプレートの階高別の組合せDB
B3: 比較用 | C3: 機種CD | D3: OP | E3: 遮煙有無 | F3: 階高（mm） | I3: ﾌｪｯｼｬｰ寸法 【員数】 | J3: 中間ブラ 【員数】 | L3: データ区分 | O3: 確認区分 | P3: 頂部テールコードサポートブラの取付範囲 | T3: 機種ID | U3: 確認対象 | V3: 根拠資料 | W3: 資料の版 | X3: 確認者 | Y3: 確認日 | Z3: 判定 | AA3: 推定行の使用可
A4: 10100000 | B4: UA-25TP800無0 | C4: UA-25TP | D4: 800 | E4: 無 | F4: 0 | G4: ～ | H4: 2640 | I4: 無し | J4: 0 | K4: 101 | L4: QR収録 | M4: UA-25TP800無 | N4: 101 | O4: 原データ | P4: 後落ち | Q4: P-6 | R4: 400 | T4: 101 | U4: UA-25TP OP800 遮煙無 | Z4: QR収録 | AA4: =IF(AND(V4<>"",W4<>"",X4<>"",COUNT(Y4)=1,Y4>0,Z4="確認済"),1,0) -> 0
A5: 10102641 | B5: UA-25TP800無2641 | C5: UA-25TP | D5: 800 | E5: 無 | F5: 2641 | G5: ～ | H5: 2715 | I5: 延長ﾄｰｶﾞｰﾄﾞ【1】 | J5: 0 | K5: 101 | L5: QR収録 | M5: UA-25TP800有 | N5: 102 | O5: 原データ | Q5: P-9 | R5: 475 | T5: 102 | U5: UA-25TP OP800 遮煙有 | Z5: QR収録 | AA5: =IF(AND(V5<>"",W5<>"",X5<>"",COUNT(Y5)=1,Y5>0,Z5="確認済"),1,0) -> 0
A6: 10102716 | B6: UA-25TP800無2716 | C6: UA-25TP | D6: 800 | E6: 無 | F6: 2716 | G6: ～ | H6: 2765 | I6: 220【1】 | J6: 0 | K6: 101 | L6: QR収録 | M6: UA-25TP900無 | N6: 103 | O6: 原データ | Q6: P-11～P-15 | R6: 1225 | T6: 103 | U6: UA-25TP OP900 遮煙無 | Z6: QR収録 | AA6: =IF(AND(V6<>"",W6<>"",X6<>"",COUNT(Y6)=1,Y6>0,Z6="確認済"),1,0) -> 0
A7: 10102766 | B7: UA-25TP800無2766 | C7: UA-25TP | D7: 800 | E7: 無 | F7: 2766 | G7: ～ | H7: 2865 | I7: 320【1】 | J7: 0 | K7: 101 | L7: QR収録 | M7: UA-25TP900有 | N7: 104 | O7: 原データ | T7: 104 | U7: UA-25TP OP900 遮煙有 | Z7: QR収録 | AA7: =IF(AND(V7<>"",W7<>"",X7<>"",COUNT(Y7)=1,Y7>0,Z7="確認済"),1,0) -> 0
A8: 10102866 | B8: UA-25TP800無2866 | C8: UA-25TP | D8: 800 | E8: 無 | F8: 2866 | G8: ～ | H8: 2965 | I8: 420【1】 | J8: 0 | K8: 101 | L8: QR収録 | M8: UA-25TP1000無 | N8: 105 | O8: 原データ | T8: 105 | U8: UA-25TP OP1000 遮煙無 | Z8: QR収録 | AA8: =IF(AND(V8<>"",W8<>"",X8<>"",COUNT(Y8)=1,Y8>0,Z8="確認済"),1,0) -> 0
A9: 10102966 | B9: UA-25TP800無2966 | C9: UA-25TP | D9: 800 | E9: 無 | F9: 2966 | G9: ～ | H9: 3065 | I9: 520【1】 | J9: 0 | K9: 101 | L9: QR収録 | M9: UA-25TP1000有 | N9: 106 | O9: 原データ | T9: 106 | U9: UA-25TP OP1000 遮煙有 | Z9: QR収録 | AA9: =IF(AND(V9<>"",W9<>"",X9<>"",COUNT(Y9)=1,Y9>0,Z9="確認済"),1,0) -> 0
A10: 10103066 | B10: UA-25TP800無3066 | C10: UA-25TP | D10: 800 | E10: 無 | F10: 3066 | G10: ～ | H10: 3165 | I10: 620【1】 | J10: 0 | K10: 101 | L10: QR収録 | M10: UA-25TP1100無 | N10: 107 | O10: 原データ | T10: 107 | U10: UA-25TP OP1100 遮煙無 | Z10: QR収録 | AA10: =IF(AND(V10<>"",W10<>"",X10<>"",COUNT(Y10)=1,Y10>0,Z10="確認済"),1,0) -> 0
A11: 10103166 | B11: UA-25TP800無3166 | C11: UA-25TP | D11: 800 | E11: 無 | F11: 3166 | G11: ～ | H11: 3265 | I11: 720【1】 | J11: 0 | K11: 101 | L11: QR収録 | M11: UA-25TP1100有 | N11: 108 | O11: 原データ | T11: 108 | U11: UA-25TP OP1100 遮煙有 | Z11: QR収録 | AA11: =IF(AND(V11<>"",W11<>"",X11<>"",COUNT(Y11)=1,Y11>0,Z11="確認済"),1,0) -> 0
A12: 10103266 | B12: UA-25TP800無3266 | C12: UA-25TP | D12: 800 | E12: 無 | F12: 3266 | G12: ～ | H12: 3365 | I12: 820【1】 | J12: 0 | K12: 101 | L12: QR収録 | M12: UAE-25T1000無 | N12: 109 | O12: 一部推定 | T12: 109 | U12: UAE-25T OP1000 遮煙無 | Z12: 未確認 | AA12: =IF(AND(V12<>"",W12<>"",X12<>"",COUNT(Y12)=1,Y12>0,Z12="確認済"),1,0) -> 0
A13: 10103366 | B13: UA-25TP800無3366 | C13: UA-25TP | D13: 800 | E13: 無 | F13: 3366 | G13: ～ | H13: 3465 | I13: 920【1】 | J13: 0 | K13: 101 | L13: QR収録 | M13: UAE-25T1000有 | N13: 110 | O13: 推定・要照合 | T13: 110 | U13: UAE-25T OP1000 遮煙有 | Z13: 未確認 | AA13: =IF(AND(V13<>"",W13<>"",X13<>"",COUNT(Y13)=1,Y13>0,Z13="確認済"),1,0) -> 0
A14: 10103466 | B14: UA-25TP800無3466 | C14: UA-25TP | D14: 800 | E14: 無 | F14: 3466 | G14: ～ | H14: 3565 | I14: 1020【1】 | J14: 0 | K14: 101 | L14: QR収録 | M14: UAE-25T1100無 | N14: 111 | O14: 推定・要照合 | T14: 111 | U14: UAE-25T OP1100 遮煙無 | Z14: 未確認 | AA14: =IF(AND(V14<>"",W14<>"",X14<>"",COUNT(Y14)=1,Y14>0,Z14="確認済"),1,0) -> 0
A15: 10103566 | B15: UA-25TP800無3566 | C15: UA-25TP | D15: 800 | E15: 無 | F15: 3566 | G15: ～ | H15: 3665 | I15: 1120【1】 | J15: 0 | K15: 101 | L15: QR収録 | M15: UAE-25T1100有 | N15: 112 | O15: 推定・要照合 | T15: 112 | U15: UAE-25T OP1100 遮煙有 | Z15: 未確認 | AA15: =IF(AND(V15<>"",W15<>"",X15<>"",COUNT(Y15)=1,Y15>0,Z15="確認済"),1,0) -> 0
A16: 10103666 | B16: UA-25TP800無3666 | C16: UA-25TP | D16: 800 | E16: 無 | F16: 3666 | G16: ～ | H16: 3765 | I16: 420【1】+800【1】 | J16: 1 | K16: 101 | L16: QR収録 | M16: UA-25TR800無 | N16: 113 | O16: 推定・要照合 | T16: 113 | U16: UA-25TR OP800 遮煙無 | Z16: 未確認 | AA16: =IF(AND(V16<>"",W16<>"",X16<>"",COUNT(Y16)=1,Y16>0,Z16="確認済"),1,0) -> 0
A17: 10103766 | B17: UA-25TP800無3766 | C17: UA-25TP | D17: 800 | E17: 無 | F17: 3766 | G17: ～ | H17: 3865 | I17: 520【1】+800【1】 | J17: 1 | K17: 101 | L17: QR収録 | M17: UA-25TR800有 | N17: 114 | O17: 推定・要照合 | T17: 114 | U17: UA-25TR OP800 遮煙有 | Z17: 未確認 | AA17: =IF(AND(V17<>"",W17<>"",X17<>"",COUNT(Y17)=1,Y17>0,Z17="確認済"),1,0) -> 0
A18: 10103866 | B18: UA-25TP800無3866 | C18: UA-25TP | D18: 800 | E18: 無 | F18: 3866 | G18: ～ | H18: 3965 | I18: 620【1】+800【1】 | J18: 1 | K18: 101 | L18: QR収録 | M18: UA-25TR900無 | N18: 115 | O18: 推定・要照合 | T18: 115 | U18: UA-25TR OP900 遮煙無 | Z18: 未確認 | AA18: =IF(AND(V18<>"",W18<>"",X18<>"",COUNT(Y18)=1,Y18>0,Z18="確認済"),1,0) -> 0
... A23: 10104366 | B23: UA-25TP800無4366 | C23: UA-25TP | D23: 800 | E23: 無 | F23: 4366 | G23: ～ | H23: 4465 | I23: 1120【1】+800【1】 | J23: 1 | K23: 101 | L23: QR収録 | M23: UA-25TB1200有 | N23: 120 | O23: 推定・要照合 | T23: 120 | U23: UA-25TB OP1200 遮煙有 | Z23: 未確認 | AA23: =IF(AND(V23<>"",W23<>"",X23<>"",COUNT(Y23)=1,Y23>0,Z23="確認済"),1,0) -> 0
A24: 10104466 | B24: UA-25TP800無4466 | C24: UA-25TP | D24: 800 | E24: 無 | F24: 4466 | G24: ～ | H24: 4565 | I24: 420【1】+800【2】 | J24: 2 | K24: 101 | L24: QR収録
A25: 10104566 | B25: UA-25TP800無4566 | C25: UA-25TP | D25: 800 | E25: 無 | F25: 4566 | G25: ～ | H25: 4665 | I25: 520【1】+800【2】 | J25: 2 | K25: 101 | L25: QR収録
A26: 10104666 | B26: UA-25TP800無4666 | C26: UA-25TP | D26: 800 | E26: 無 | F26: 4666 | G26: ～ | H26: 4765 | I26: 620【1】+800【2】 | J26: 2 | K26: 101 | L26: QR収録
A27: 10104766 | B27: UA-25TP800無4766 | C27: UA-25TP | D27: 800 | E27: 無 | F27: 4766 | G27: ～ | H27: 4865 | I27: 720【1】+800【2】 | J27: 2 | K27: 101 | L27: QR収録
A28: 10104866 | B28: UA-25TP800無4866 | C28: UA-25TP | D28: 800 | E28: 無 | F28: 4866 | G28: ～ | H28: 4965 | I28: 820【1】+800【2】 | J28: 2 | K28: 101 | L28: QR収録
A29: 10104966 | B29: UA-25TP800無4966 | C29: UA-25TP | D29: 800 | E29: 無 | F29: 4966 | G29: ～ | H29: 5065 | I29: 920【1】+800【2】 | J29: 2 | K29: 101 | L29: QR収録
A30: 10105066 | B30: UA-25TP800無5066 | C30: UA-25TP | D30: 800 | E30: 無 | F30: 5066 | G30: ～ | H30: 5165 | I30: 1020【1】+800【2】 | J30: 2 | K30: 101 | L30: QR収録
A31: 10105166 | B31: UA-25TP800無5166 | C31: UA-25TP | D31: 800 | E31: 無 | F31: 5166 | G31: ～ | H31: 5265 | I31: 1120【1】+800【2】 | J31: 2 | K31: 101 | L31: QR収録
A32: 10105266 | B32: UA-25TP800無5266 | C32: UA-25TP | D32: 800 | E32: 無 | F32: 5266 | G32: ～ | H32: 5365 | I32: 420【1】+800【3】 | J32: 3 | K32: 101 | L32: QR収録
A33: 10105366 | B33: UA-25TP800無5366 | C33: UA-25TP | D33: 800 | E33: 無 | F33: 5366 | G33: ～ | H33: 5465 | I33: 520【1】+800【3】 | J33: 3 | K33: 101 | L33: QR収録
A34: 10105466 | B34: UA-25TP800無5466 | C34: UA-25TP | D34: 800 | E34: 無 | F34: 5466 | G34: ～ | H34: 5565 | I34: 620【1】+800【3】 | J34: 3 | K34: 101 | L34: QR収録
A35: 10105566 | B35: UA-25TP800無5566 | C35: UA-25TP | D35: 800 | E35: 無 | F35: 5566 | G35: ～ | H35: 5665 | I35: 720【1】+800【3】 | J35: 3 | K35: 101 | L35: QR収録
... A1123: 12007951 | B1123: UA-25TB1200有7951 | C1123: UA-25TB | D1123: 1200 | E1123: 有 | F1123: 7951 | G1123: ～ | H1123: 8050 | I1123: 720【1】+800【6】 | J1123: 6 | K1123: 120 | L1123: 推定補完
